Workbook
Name College: #REF!
Name College: #REF!
Name College: #REF!
Name College: #REF!
Name College: #REF!
Name College: #REF!
Name College: #REF!
Name College: #REF!
Name College: #REF!
Name College: #REF!
Name College: #REF!
Name College: #REF!
Name College: #REF!
Name College: #REF!
Name College: #REF!
Name College: #REF!
Name College: #REF!
Name College: #REF!
Name College: #REF!
Name College: #REF!
Name College: #REF!
Name College: #REF!
Name College: #REF!
Name College: #REF!
Name College: #REF!
Name College: #REF!
Name College: #REF!
Name College: #REF!
Name d: #REF!
Name d: #REF!
Name d: #REF!
Name d: #REF!
Name d: #REF!
Name d: #REF!
Name d: #REF!
Name d: #REF!
Name d: #REF!
Name d: #REF!
Name d: #REF!
Name d: #REF!
Name d: #REF!
Name d: #REF!
Name d: #REF!
Name d: #REF!
Name d: #REF!
Name d: #REF!
Name d: #REF!
Name d: #REF!
Name d: #REF!
Name d: #REF!
Name d: #REF!
Name d: #REF!
Name d: #REF!
Name d: #REF!
Name d: #REF!
Name fg: #REF!
Name fg: #REF!
Name JR_PAGE_ANCHOR_0_1: #REF!
Name JR_PAGE_ANCHOR_0_1: #REF!
Name JR_PAGE_ANCHOR_0_1: #REF!

Sheet 1UniNo
B1: Table 1. States/UTs & Type - Wise Number of Universities registered in AISHE
A2: S.No. | B2: States/UTs | C2: Central University | D2: Central Open University | E2: Institute of National Importance | F2: State Public University | G2: Institute under State Legislature Act | H2: State Open University | I2: State Private University | J2: State Private Open University | K2: Deemed University-Government | L2: Deemed University-Government Aided | M2: Deemed University-Private | N2: Grand Total
A3: 1 | B3: 2 | C3: 3 | D3: 4 | E3: 5 | F3: 6 | G3: 7 | H3: 8 | I3: 9 | J3: 10 | K3: 11 | L3: 12 | M3: 13 | N3: 14
A4: 1 | B4: Andhra Pradesh | C4: 3 | E4: 10 | F4: 24 | G4: 1 | I4: 5 | M4: 4 | N4: 47
A5: 2 | B5: Arunachal Pradesh | C5: 1 | E5: 1 | I5: 6 | J5: 1 | K5: 1 | N5: 10
A6: 3 | B6: Assam | C6: 2 | E6: 5 | F6: 15 | H6: 1 | I6: 6 | K6: 1 | N6: 30
A7: 4 | B7: Bihar | C7: 4 | E7: 6 | F7: 17 | G7: 1 | H7: 1 | I7: 7 | K7: 1 | N7: 37
A8: 5 | B8: Chandigarh | E8: 1 | F8: 1 | K8: 1 | N8: 3
A9: 6 | B9: Chhattisgarh | C9: 1 | E9: 4 | F9: 14 | H9: 1 | I9: 14 | N9: 34
A10: 7 | B10: Delhi | C10: 6 | D10: 1 | E10: 6 | F10: 9 | K10: 6 | L10: 1 | M10: 1 | N10: 30
A11: 8 | B11: Goa | E11: 2 | F11: 1 | N11: 3
A12: 9 | B12: Gujarat | C12: 1 | E12: 9 | F12: 26 | H12: 1 | I12: 51 | K12: 1 | L12: 1 | M12: 1 | N12: 91
A13: 10 | B13: Haryana | C13: 1 | E13: 5 | F13: 20 | I13: 24 | K13: 3 | M13: 3 | N13: 56
A14: 11 | B14: Himachal Pradesh | C14: 1 | E14: 5 | F14: 7 | I14: 17 | N14: 30
A15: 12 | B15: Jammu and Kashmir | C15: 2 | E15: 4 | F15: 9 | G15: 1 | N15: 16
A16: 13 | B16: Jharkhand | C16: 1 | E16: 5 | F16: 11 | I16: 15 | M16: 1 | N16: 33
A17: 14 | B17: Karnataka | C17: 1 | E17: 6 | F17: 33 | H17: 1 | I17: 20 | K17: 2 | M17: 12 | N17: 75
A18: 15 | B18: Kerala | C18: 1 | E18: 6 | F18: 14 | H18: 1 | K18: 2 | M18: 1 | N18: 25
A19: 16 | B19: Ladakh | F19: 1 | K19: 1 | N19: 2
A20: 17 | B20: Madhya Pradesh | C20: 2 | E20: 10 | F20: 23 | H20: 1 | I20: 40 | K20: 1 | N20: 77
A21: 18 | B21: Maharashtra | C21: 1 | E21: 7 | F21: 23 | H21: 1 | I21: 21 | K21: 7 | L21: 2 | M21: 12 | N21: 74
A22: 19 | B22: Manipur | C22: 3 | E22: 2 | F22: 3 | I22: 2 | N22: 10
A23: 20 | B23: Meghalaya | C23: 1 | E23: 2 | I23: 8 | N23: 11
A24: 21 | B24: Mizoram | C24: 1 | E24: 1 | I24: 1 | N24: 3
A25: 22 | B25: Nagaland | C25: 1 | E25: 1 | I25: 4 | N25: 6
A26: 23 | B26: Odisha | C26: 1 | E26: 5 | F26: 19 | H26: 1 | I26: 8 | M26: 3 | N26: 37
A27: 24 | B27: Puducherry | C27: 1 | E27: 2 | M27: 1 | N27: 4
A28: 25 | B28: Punjab | C28: 1 | E28: 6 | F28: 12 | H28: 1 | I28: 18 | K28: 1 | M28: 1 | N28: 40
A29: 26 | B29: Rajasthan | C29: 1 | E29: 5 | F29: 26 | G29: 1 | H29: 1 | I29: 49 | M29: 7 | N29: 90
A30: 27 | B30: Sikkim | C30: 1 | E30: 1 | F30: 1 | I30: 6 | N30: 9
A31: 28 | B31: Tamil Nadu | C31: 2 | E31: 7 | F31: 21 | H31: 1 | I31: 3 | L31: 2 | M31: 26 | N31: 62
A32: 29 | B32: Telangana | C32: 3 | E32: 4 | F32: 15 | G32: 1 | H32: 1 | I32: 4 | K32: 1 | M32: 2 | N32: 31
A33: 30 | B33: Tripura | C33: 1 | E33: 2 | F33: 1 | I33: 1 | N33: 5
A34: 31 | B34: Uttar Pradesh | C34: 6 | E34: 11 | F34: 32 | G34: 1 | H34: 1 | I34: 31 | K34: 2 | L34: 3 | M34: 4 | N34: 91
A35: 32 | B35: Uttarakhand | C35: 1 | E35: 4 | F35: 10 | H35: 1 | I35: 19 | K35: 1 | L35: 1 | M35: 1 | N35: 38
A36: 33 | B36: West Bengal | C36: 1 | E36: 8 | F36: 35 | H36: 1 | I36: 11 | K36: 1 | M36: 1 | N36: 58
A37: All India | C37: 53 | D37: 1 | E37: 153 | F37: 423 | G37: 6 | H37: 16 | I37: 391 | J37: 1 | K37: 33 | L37: 10 | M37: 81 | N37: 1168
B38: In UTs of , Andaman & Nicobar Islands, Dadra & Nagar Haveli, Daman & Diu and Lakshadweep, there is no University.

Sheet 1InsResponse
B1: Table 1(a). | C1: Total Number of Institutions Registered and Responded in AISHE 2021-22
A2: S.No. | B2: States/UTs | C2: Unversities | F2: Colleges | I2: Standalone Institutions | L2: Total
C3: Registered | D3: Responded | E3: % of Response | F3: Registered | G3: Responded | H3: % of Response | I3: Registered | J3: Responded | K3: % of Response | L3: Registered | M3: Responded | N3: % of Response
A4: 1 | B4: 2 | C4: 3 | D4: 4 | E4: 5 | F4: 6 | G4: 7 | H4: 8 | I4: 9 | J4: 10 | K4: 11 | L4: 12 | M4: 13 | N4: 14
A5: 1 | B5: A & N Islands | F5: 9 | G5: 9 | H5: =G5/F5 -> 1 | I5: 1 | J5: 1 | K5: =J5/I5 -> 1 | L5: 10 | M5: 10 | N5: =M5/L5 -> 1
A6: 2 | B6: Andhra Pradesh | C6: 47 | D6: 47 | E6: =D6/C6 -> 1 | F6: 2602 | G6: 2582 | H6: =G6/F6 -> 0.9923136 | I6: 722 | J6: 633 | K6: =J6/I6 -> 0.8767313 | L6: 3371 | M6: 3262 | N6: =M6/L6 -> 0.96766538
A7: 3 | B7: Arunachal Pradesh | C7: 10 | D7: 10 | E7: =D7/C7 -> 1 | F7: 44 | G7: 43 | H7: =G7/F7 -> 0.97727273 | I7: 20 | J7: 20 | K7: =J7/I7 -> 1 | L7: 74 | M7: 73 | N7: =M7/L7 -> 0.98648649
A8: 4 | B8: Assam | C8: 30 | D8: 30 | E8: =D8/C8 -> 1 | F8: 607 | G8: 553 | H8: =G8/F8 -> 0.91103789 | I8: 99 | J8: 89 | K8: =J8/I8 -> 0.8989899 | L8: 736 | M8: 672 | N8: =M8/L8 -> 0.91304348
A9: 5 | B9: Bihar | C9: 37 | D9: 37 | E9: =D9/C9 -> 1 | F9: 1092 | G9: 1072 | H9: =G9/F9 -> 0.98168498 | I9: 315 | J9: 278 | K9: =J9/I9 -> 0.88253968 | L9: 1444 | M9: 1387 | N9: =M9/L9 -> 0.96052632
A10: 6 | B10: Chandigarh | C10: 3 | D10: 3 | E10: =D10/C10 -> 1 | F10: 26 | G10: 26 | H10: =G10/F10 -> 1 | I10: 10 | J10: 10 | K10: =J10/I10 -> 1 | L10: 39 | M10: 39 | N10: =M10/L10 -> 1
A11: 7 | B11: Chhattisgarh | C11: 34 | D11: 34 | E11: =D11/C11 -> 1 | F11: 917 | G11: 895 | H11: =G11/F11 -> 0.97600872 | I11: 80 | J11: 70 | K11: =J11/I11 -> 0.875 | L11: 1031 | M11: 999 | N11: =M11/L11 -> 0.96896217
A12: 8 | B12: Delhi | C12: 30 | D12: 30 | E12: =D12/C12 -> 1 | F12: 188 | G12: 171 | H12: =G12/F12 -> 0.90957447 | I12: 107 | J12: 87 | K12: =J12/I12 -> 0.81308411 | L12: 325 | M12: 288 | N12: =M12/L12 -> 0.88615385
A13: 9 | B13: Goa | C13: 3 | D13: 3 | E13: =D13/C13 -> 1 | F13: 62 | G13: 62 | H13: =G13/F13 -> 1 | I13: 17 | J13: 17 | K13: =J13/I13 -> 1 | L13: 82 | M13: 82 | N13: =M13/L13 -> 1
A14: 10 | B14: Gujarat | C14: 91 | D14: 91 | E14: =D14/C14 -> 1 | F14: 2395 | G14: 2374 | H14: =G14/F14 -> 0.99123173 | I14: 327 | J14: 327 | K14: =J14/I14 -> 1 | L14: 2813 | M14: 2792 | N14: =M14/L14 -> 0.99253466
A15: 11 | B15: Haryana | C15: 56 | D15: 56 | E15: =D15/C15 -> 1 | F15: 1090 | G15: 1089 | H15: =G15/F15 -> 0.99908257 | I15: 258 | J15: 257 | K15: =J15/I15 -> 0.99612403 | L15: 1404 | M15: 1402 | N15: =M15/L15 -> 0.9985755
A16: 12 | B16: Himachal Pradesh | C16: 30 | D16: 29 | E16: =D16/C16 -> 0.96666667 | F16: 349 | G16: 348 | H16: =G16/F16 -> 0.99713467 | I16: 86 | J16: 82 | K16: =J16/I16 -> 0.95348837 | L16: 465 | M16: 459 | N16: =M16/L16 -> 0.98709677
A17: 13 | B17: Jammu and Kashmir | C17: 16 | D17: 16 | E17: =D17/C17 -> 1 | F17: 341 | G17: 337 | H17: =G17/F17 -> 0.98826979 | I17: 164 | J17: 145 | K17: =J17/I17 -> 0.88414634 | L17: 521 | M17: 498 | N17: =M17/L17 -> 0.95585413
... A21: 17 | B21: Ladakh | C21: 2 | D21: 2 | E21: =D21/C21 -> 1 | F21: 6 | G21: 6 | H21: =G21/F21 -> 1 | I21: 7 | J21: 6 | K21: =J21/I21 -> 0.85714286 | L21: 15 | M21: 14 | N21: =M21/L21 -> 0.93333333
A22: 18 | B22: Lakshadweep*
A23: 19 | B23: Madhya Pradesh | C23: 77 | D23: 77 | E23: =D23/C23 -> 1 | F23: 2742 | G23: 2464 | H23: =G23/F23 -> 0.89861415 | I23: 401 | J23: 290 | K23: =J23/I23 -> 0.72319202 | L23: 3220 | M23: 2831 | N23: =M23/L23 -> 0.87919255
A24: 20 | B24: Maharashtra | C24: 74 | D24: 74 | E24: =D24/C24 -> 1 | F24: 4692 | G24: 4685 | H24: =G24/F24 -> 0.9985081 | I24: 2237 | J24: 2087 | K24: =J24/I24 -> 0.93294591 | L24: 7003 | M24: 6846 | N24: =M24/L24 -> 0.97758104
A25: 21 | B25: Manipur | C25: 10 | D25: 9 | E25: =D25/C25 -> 0.9 | F25: 108 | G25: 103 | H25: =G25/F25 -> 0.9537037 | I25: 36 | J25: 34 | K25: =J25/I25 -> 0.94444444 | L25: 154 | M25: 146 | N25: =M25/L25 -> 0.94805195
A26: 22 | B26: Meghalaya | C26: 11 | D26: 11 | E26: =D26/C26 -> 1 | F26: 77 | G26: 69 | H26: =G26/F26 -> 0.8961039 | I26: 23 | J26: 22 | K26: =J26/I26 -> 0.95652174 | L26: 111 | M26: 102 | N26: =M26/L26 -> 0.91891892
A27: 23 | B27: Mizoram | C27: 3 | D27: 3 | E27: =D27/C27 -> 1 | F27: 40 | G27: 40 | H27: =G27/F27 -> 1 | I27: 52 | J27: 50 | K27: =J27/I27 -> 0.96153846 | L27: 95 | M27: 93 | N27: =M27/L27 -> 0.97894737
A28: 24 | B28: Nagaland | C28: 6 | D28: 6 | E28: =D28/C28 -> 1 | F28: 69 | G28: 68 | H28: =G28/F28 -> 0.98550725 | I28: 23 | J28: 22 | K28: =J28/I28 -> 0.95652174 | L28: 98 | M28: 96 | N28: =M28/L28 -> 0.97959184
A29: 25 | B29: Odisha | C29: 37 | D29: 37 | E29: =D29/C29 -> 1 | F29: 1300 | G29: 1289 | H29: =G29/F29 -> 0.99153846 | I29: 521 | J29: 521 | K29: =J29/I29 -> 1 | L29: 1858 | M29: 1847 | N29: =M29/L29 -> 0.99407966
A30: 26 | B30: Puducherry | C30: 4 | D30: 4 | E30: =D30/C30 -> 1 | F30: 82 | G30: 68 | H30: =G30/F30 -> 0.82926829 | I30: 12 | J30: 11 | K30: =J30/I30 -> 0.91666667 | L30: 98 | M30: 83 | N30: =M30/L30 -> 0.84693878
A31: 27 | B31: Punjab | C31: 40 | D31: 40 | E31: =D31/C31 -> 1 | F31: 1044 | G31: 1037 | H31: =G31/F31 -> 0.99329502 | I31: 367 | J31: 357 | K31: =J31/I31 -> 0.97275204 | L31: 1451 | M31: 1434 | N31: =M31/L31 -> 0.98828394
A32: 28 | B32: Rajasthan | C32: 90 | D32: 89 | E32: =D32/C32 -> 0.98888889 | F32: 3934 | G32: 3521 | H32: =G32/F32 -> 0.89501779 | I32: 574 | J32: 465 | K32: =J32/I32 -> 0.81010453 | L32: 4598 | M32: 4075 | N32: =M32/L32 -> 0.88625489
A33: 29 | B33: Sikkim | C33: 9 | D33: 7 | E33: =D33/C33 -> 0.77777778 | F33: 24 | G33: 20 | H33: =G33/F33 -> 0.83333333 | I33: 8 | J33: 8 | K33: =J33/I33 -> 1 | L33: 41 | M33: 35 | N33: =M33/L33 -> 0.85365854
A34: 30 | B34: Tamil Nadu | C34: 62 | D34: 62 | E34: =D34/C34 -> 1 | F34: 2829 | G34: 2807 | H34: =G34/F34 -> 0.9922234 | I34: 899 | J34: 867 | K34: =J34/I34 -> 0.96440489 | L34: 3790 | M34: 3736 | N34: =M34/L34 -> 0.98575198
A35: 31 | B35: Telangana | C35: 31 | D35: 31 | E35: =D35/C35 -> 1 | F35: 2083 | G35: 1940 | H35: =G35/F35 -> 0.93134902 | I35: 459 | J35: 391 | K35: =J35/I35 -> 0.85185185 | L35: 2573 | M35: 2362 | N35: =M35/L35 -> 0.91799456
A36: 32 | B36: D & N Haveli and Daman & Diu | F36: 19 | G36: 19 | H36: =G36/F36 -> 1 | I36: 1 | J36: 1 | K36: =J36/I36 -> 1 | L36: 20 | M36: 20 | N36: =M36/L36 -> 1
A37: 33 | B37: Tripura | C37: 5 | D37: 5 | E37: =D37/C37 -> 1 | F37: 54 | G37: 54 | H37: =G37/F37 -> 1 | I37: 14 | J37: 13 | K37: =J37/I37 -> 0.92857143 | L37: 73 | M37: 72 | N37: =M37/L37 -> 0.98630137
A38: 34 | B38: Uttar Pradesh | C38: 91 | D38: 91 | E38: =D38/C38 -> 1 | F38: 8375 | G38: 7182 | H38: =G38/F38 -> 0.85755224 | I38: 1194 | J38: 939 | K38: =J38/I38 -> 0.78643216 | L38: 9660 | M38: 8212 | N38: =M38/L38 -> 0.85010352
A39: 35 | B39: Uttarakhand | C39: 38 | D39: 37 | E39: =D39/C39 -> 0.97368421 | F39: 500 | G39: 402 | H39: =G39/F39 -> 0.804 | I39: 156 | J39: 141 | K39: =J39/I39 -> 0.90384615 | L39: 694 | M39: 580 | N39: =M39/L39 -> 0.83573487
A40: 36 | B40: West Bengal | C40: 58 | D40: 58 | E40: =D40/C40 -> 1 | F40: 1514 | G40: 1510 | H40: =G40/F40 -> 0.99735799 | I40: 574 | J40: 571 | K40: =J40/I40 -> 0.99477352 | L40: 2146 | M40: 2139 | N40: =M40/L40 -> 0.99673812
A41: All India | C41: 1168 | D41: 1162 | E41: =D41/C41 -> 0.99486301 | F41: 45473 | G41: 42825 | H41: =G41/F41 -> 0.94176764 | I41: 12002 | J41: 10576 | K41: =J41/I41 -> 0.88118647 | L41: 58643 | M41: 54563 | N41: =M41/L41 -> 0.93042648
A42: * Lakshadweep dose not have any University/Colleges & Stand Alone Institutions. However 3 PG/Off-shore campus of University of Calicut, Malappuram are functiong from Lakshadweep.

Sheet 2University-Specialisation
B1: Table 2. | C1: States/UTs & Specialisation-wise Number of Universities (Based on Actual Response) | N1: =C1 -> States/UTs & Specialisation-wise Number of Universities (Based on Actual Response)
A2: S.No. | B2: States/UTs | C2: General | D2: Agriculture | E2: Education | F2: Chartered Accountant | G2: Cultural Studies | H2: Fine Arts | I2: Fisheries | J2: Gandhian / Religious Study | K2: Journalism & Mass Communication | L2: Language | M2: Law | N2: Management | O2: Medical | P2: Oriental Learning | Q2: Rural Development | R2: Sanskrit | S2: Science | T2: Social Science | U2: Sports/Yoga/Physical Education | V2: Technical | W2: Veterinary | X2: Other | Y2: Grand Total
A3: 1 | B3: 2 | C3: 3 | D3: 4 | E3: 5 | F3: 6 | G3: 7 | H3: 8 | I3: 9 | J3: 10 | K3: 11 | L3: 12 | M3: 13 | N3: 14 | O3: 15 | P3: 16 | Q3: 17 | R3: 18 | S3: 19 | T3: 20 | U3: 21 | V3: 22 | W3: 23 | X3: 24 | Y3: 25
A4: 1 | B4: Andhra Pradesh | C4: 21 | D4: 2 | H4: 1 | L4: 1 | M4: 1 | N4: 1 | O4: 3 | R4: 2 | S4: 2 | V4: 12 | W4: 1 | Y4: 47
A5: 2 | B5: Arunachal Pradesh | C5: 7 | O5: 1 | V5: 2 | Y5: 10
A6: 3 | B6: Assam | C6: 16 | D6: 1 | G6: 1 | M6: 1 | O6: 2 | R6: 1 | U6: 1 | V6: 7 | Y6: 30
A7: 4 | B7: Bihar | C7: 25 | D7: 2 | N7: 1 | O7: 3 | P7: 1 | R7: 1 | V7: 3 | W7: 1 | Y7: 37
A8: 5 | B8: Chandigarh | C8: 1 | O8: 1 | V8: 1 | Y8: 3
A9: 6 | B9: Chhattisgarh | C9: 23 | E9: 1 | K9: 1 | M9: 1 | N9: 2 | O9: 2 | V9: 4 | Y9: 34
A10: 7 | B10: Delhi | C10: 10 | D10: 1 | E10: 1 | H10: 1 | M10: 2 | O10: 3 | R10: 2 | S10: 1 | V10: 8 | X10: 1 | Y10: 30
A11: 8 | B11: Goa | C11: 1 | V11: 2 | Y11: 3
A12: 9 | B12: Gujarat | C12: 57 | D12: 4 | E12: 1 | M12: 1 | N12: 2 | O12: 4 | R12: 1 | S12: 3 | U12: 2 | V12: 15 | X12: 1 | Y12: 91
A13: 10 | B13: Haryana | C13: 34 | D13: 3 | M13: 1 | N13: 1 | O13: 3 | R13: 1 | S13: 3 | T13: 1 | V13: 8 | W13: 1 | Y13: 56
A14: 11 | B14: Himachal Pradesh | C14: 16 | D14: 2 | F14: 1 | M14: 1 | N14: 1 | O14: 1 | V14: 7 | Y14: 29
A15: 12 | B15: Jammu and Kashmir | C15: 8 | D15: 2 | N15: 1 | O15: 2 | S15: 1 | V15: 2 | Y15: 16
A16: 13 | B16: Jharkhand | C16: 21 | D16: 1 | F16: 1 | M16: 1 | N16: 1 | O16: 1 | V16: 6 | X16: 1 | Y16: 33
A17: 14 | B17: Karnataka | C17: 44 | D17: 5 | H17: 1 | M17: 2 | N17: 1 | O17: 5 | Q17: 1 | R17: 1 | S17: 4 | T17: 2 | U17: 1 | V17: 7 | W17: 1 | Y17: 75
A18: 15 | B18: Kerala | C18: 8 | D18: 1 | I18: 1 | L18: 1 | M18: 1 | N18: 1 | O18: 2 | R18: 1 | S18: 2 | V18: 5 | W18: 1 | X18: 1 | Y18: 25
A19: 16 | B19: Ladakh | C19: 1 | P19: 1 | Y19: 2
A20: 17 | B20: Madhya Pradesh | C20: 48 | D20: 2 | H20: 1 | J20: 1 | K20: 1 | L20: 1 | M20: 2 | N20: 1 | O20: 3 | R20: 2 | S20: 3 | T20: 1 | U20: 1 | V20: 10 | Y20: 77
A21: 18 | B21: Maharashtra | C21: 37 | D21: 5 | H21: 1 | I21: 1 | L21: 1 | M21: 3 | N21: 2 | O21: 7 | R21: 1 | S21: 4 | T21: 3 | V21: 8 | W21: 1 | Y21: 74
A22: 19 | B22: Manipur | C22: 3 | D22: 1 | G22: 1 | U22: 1 | V22: 3 | Y22: 9
A23: 20 | B23: Meghalaya | C23: 6 | F23: 1 | N23: 1 | S23: 1 | V23: 2 | Y23: 11
A24: 21 | B24: Mizoram | C24: 1 | F24: 1 | V24: 1 | Y24: 3
A25: 22 | B25: Nagaland | C25: 4 | F25: 1 | V25: 1 | Y25: 6
A26: 23 | B26: Odisha | C26: 19 | D26: 1 | G26: 1 | M26: 2 | N26: 1 | O26: 2 | R26: 1 | S26: 1 | T26: 1 | V26: 8 | Y26: 37
A27: 24 | B27: Puducherry | C27: 2 | O27: 1 | V27: 1 | Y27: 4
A28: 25 | B28: Punjab | C28: 22 | D28: 1 | M28: 1 | N28: 1 | O28: 4 | S28: 1 | U28: 1 | V28: 8 | W28: 1 | Y28: 40
A29: 26 | B29: Rajasthan | C29: 56 | D29: 5 | K29: 1 | M29: 2 | N29: 1 | O29: 8 | R29: 2 | S29: 1 | U29: 1 | V29: 11 | W29: 1 | Y29: 89
A30: 27 | B30: Sikkim | C30: 5 | F30: 1 | V30: 1 | Y30: 7
A31: 28 | B31: Tamil Nadu | C31: 28 | D31: 1 | H31: 1 | I31: 1 | L31: 1 | M31: 2 | N31: 1 | O31: 3 | Q31: 1 | S31: 2 | U31: 3 | V31: 17 | W31: 1 | Y31: 62
A32: 29 | B32: Telangana | C32: 15 | D32: 2 | H32: 1 | L32: 1 | M32: 1 | O32: 4 | P32: 1 | V32: 5 | W32: 1 | Y32: 31
A33: 30 | B33: Tripura | C33: 2 | F33: 1 | V33: 2 | Y33: 5
A34: 31 | B34: Uttar Pradesh | C34: 51 | D34: 6 | E34: 1 | H34: 1 | J34: 1 | L34: 1 | M34: 1 | N34: 1 | O34: 9 | R34: 1 | S34: 1 | V34: 14 | W34: 2 | X34: 1 | Y34: 91
A35: 32 | B35: Uttarakhand | C35: 23 | D35: 3 | N35: 1 | O35: 3 | R35: 2 | V35: 5 | Y35: 37
A36: 33 | B36: West Bengal | C36: 40 | D36: 2 | E36: 1 | I36: 1 | L36: 1 | M36: 1 | N36: 1 | O36: 2 | S36: 3 | V36: 6 | Y36: 58
A37: All India | C37: 655 | D37: 53 | E37: 5 | F37: 7 | G37: 3 | H37: 8 | I37: 4 | J37: 2 | K37: 3 | L37: 8 | M37: 27 | N37: 23 | O37: 79 | P37: 3 | Q37: 2 | R37: 19 | S37: 33 | T37: 8 | U37: 11 | V37: 192 | W37: 12 | X37: 5 | Y37: 1162

Sheet 3Collegerange
B1: Table 3. States/UTs-wise Distribution of Districts in Different Ranges of number of Colleges
A2: S.No. | B2: States/UTs | C2: Number of College
C3: Less than 10 | D3: 10-19 | E3: 20-49 | F3: 50-99 | G3: 100-199 | H3: 200-299 | I3: 300-399 | J3: 400-499 | K3: 500-999 | L3: More than 1000
A4: 1 | B4: 2 | C4: 3 | D4: 4 | E4: 5 | F4: 6 | G4: 7 | H4: 8 | I4: 9 | J4: 10 | K4: 11 | L4: 12
A5: 1 | B5: A & N Islands | C5: 3
A6: 2 | B6: Andhra Pradesh | C6: 4 | G6: 7 | H6: 6
A7: 3 | B7: Arunachal Pradesh | C7: 15 | D7: 1
A8: 4 | B8: Assam | C8: 7 | D8: 12 | E8: 11 | G8: 1
A9: 5 | B9: Bihar | C9: 5 | D9: 12 | E9: 16 | F9: 4 | G9: 1
A10: 6 | B10: Chandigarh | E10: 1
A11: 7 | B11: Chhattisgarh | C11: 5 | D11: 8 | E11: 8 | F11: 3 | G11: 3
A12: 8 | B12: Delhi | C12: 3 | D12: 4 | E12: 4
A13: 9 | B13: Goa | E13: 2
A14: 10 | B14: Gujarat | C14: 1 | D14: 4 | E14: 10 | F14: 9 | G14: 8 | H14: 1
A15: 11 | B15: Haryana | C15: 1 | D15: 1 | E15: 10 | F15: 10
A16: 12 | B16: Himachal Pradesh | C16: 2 | D16: 3 | E16: 5 | F16: 2
A17: 13 | B17: Jammu and Kashmir | C17: 9 | D17: 6 | E17: 4 | F17: 1
A18: 14 | B18: Jharkhand | C18: 10 | D18: 9 | E18: 4 | F18: 1
A19: 15 | B19: Karnataka | C19: 1 | E19: 4 | F19: 12 | G19: 10 | H19: 2 | I19: 1 | L19: 1
A20: 16 | B20: Kerala | E20: 1 | F20: 6 | G20: 7
A21: 17 | B21: Ladakh | C21: 2
A22: 18 | B22: Lakshadweep
A23: 19 | B23: Madhya Pradesh | C23: 4 | D23: 6 | E23: 29 | F23: 8 | G23: 2 | H23: 2 | I23: 1
A24: 20 | B24: Maharashtra | E24: 3 | F24: 12 | G24: 14 | H24: 5 | I24: 1 | J24: 1
A25: 21 | B25: Manipur | C25: 7 | D25: 3 | E25: 2
A26: 22 | B26: Meghalaya | C26: 7 | D26: 1 | E26: 1
A27: 23 | B27: Mizoram | C27: 7 | E27: 1
A28: 24 | B28: Nagaland | C28: 9 | E28: 2
A29: 25 | B29: Odisha | C29: 2 | D29: 5 | E29: 16 | F29: 4 | G29: 2 | H29: 1
A30: 26 | B30: Puducherry | C30: 2 | D30: 1 | F30: 1
A31: 27 | B31: Punjab | D31: 3 | E31: 10 | F31: 8 | G31: 1
A32: 28 | B32: Rajasthan | D32: 2 | E32: 7 | F32: 10 | G32: 10 | H32: 2 | I32: 1 | K32: 1
A33: 29 | B33: Sikkim | C33: 3 | D33: 1
A34: 30 | B34: Tamil Nadu | C34: 1 | D34: 4 | E34: 10 | F34: 14 | G34: 7 | H34: 2
A35: 31 | B35: Telangana | C35: 16 | D35: 3 | E35: 3 | F35: 2 | G35: 6 | I35: 1 | J35: 1
A36: 32 | B36: D & N Haveli and Daman & Diu | C36: 3
A37: 33 | B37: Tripura | C37: 6 | E37: 1
A38: 34 | B38: Uttar Pradesh | D38: 3 | E38: 14 | F38: 26 | G38: 22 | H38: 8 | I38: 2
A39: 35 | B39: Uttarakhand | C39: 2 | D39: 5 | E39: 3 | F39: 1 | G39: 2
A40: 36 | B40: West Bengal | C40: 2 | E40: 7 | F40: 8 | G40: 5
...

Sheet 4CollegeIndicator
A1: Table 4. Number of College per Lakh Population(18-23 years), Average Enrolment per College
A2: S.No. | B2: States/UTs | C2: No. of College registered with AISHE | D2: No. of College per lakh population | E2: Average Enrolment*
A4: 1 | B4: 2 | C4: 3 | D4: 4 | E4: 5
A5: 1 | B5: A & N Islands | C5: 9 | D5: 17.813795 | E5: =VLOOKUP($B5,'[1]8CollegeAct'!$B$5:$AF$40,31,0) -> 808
A6: 2 | B6: Andhra Pradesh | C6: 2602 | D6: 49.23368 | E6: =VLOOKUP($B6,'[1]8CollegeAct'!$B$5:$AF$40,31,0) -> 554
A7: 3 | B7: Arunachal Pradesh | C7: 44 | D7: 24.76362 | E7: =VLOOKUP($B7,'[1]8CollegeAct'!$B$5:$AF$40,31,0) -> 666
A8: 4 | B8: Assam | C8: 607 | D8: 15.10326 | E8: =VLOOKUP($B8,'[1]8CollegeAct'!$B$5:$AF$40,31,0) -> 906
A9: 5 | B9: Bihar | C9: 1092 | D9: 7.102901 | E9: =VLOOKUP($B9,'[1]8CollegeAct'!$B$5:$AF$40,31,0) -> 2088
A10: 6 | B10: Chandigarh | C10: 26 | D10: 15.184312 | E10: =VLOOKUP($B10,'[1]8CollegeAct'!$B$5:$AF$40,31,0) -> 1888
A11: 7 | B11: Chhattisgarh | C11: 917 | D11: 27.356802 | E11: =VLOOKUP($B11,'[1]8CollegeAct'!$B$5:$AF$40,31,0) -> 606
A12: 8 | B12: Delhi | C12: 188 | D12: 8.0376229 | E12: =VLOOKUP($B12,'[1]8CollegeAct'!$B$5:$AF$40,31,0) -> 1752
A13: 9 | B13: Goa | C13: 62 | D13: 33.929788 | E13: =VLOOKUP($B13,'[1]8CollegeAct'!$B$5:$AF$40,31,0) -> 680
A14: 10 | B14: Gujarat | C14: 2395 | D14: 32.031563 | E14: =VLOOKUP($B14,'[1]8CollegeAct'!$B$5:$AF$40,31,0) -> 537
A15: 11 | B15: Haryana | C15: 1090 | D15: 32.910628 | E15: =VLOOKUP($B15,'[1]8CollegeAct'!$B$5:$AF$40,31,0) -> 614
A16: 12 | B16: Himachal Pradesh | C16: 349 | D16: 47.03504 | E16: =VLOOKUP($B16,'[1]8CollegeAct'!$B$5:$AF$40,31,0) -> 577
... A21: 17 | B21: Ladakh | C21: 6 | D21: 15.585734 | E21: =VLOOKUP($B21,'[1]8CollegeAct'!$B$5:$AF$40,31,0) -> 514
A22: 18 | B22: Lakshadweep
A23: 19 | B23: Madhya Pradesh | C23: 2742 | D23: 28.297214 | E23: =VLOOKUP($B23,'[1]8CollegeAct'!$B$5:$AF$40,31,0) -> 808
A24: 20 | B24: Maharashtra | C24: 4692 | D24: 36.189742 | E24: =VLOOKUP($B24,'[1]8CollegeAct'!$B$5:$AF$40,31,0) -> 685
A25: 21 | B25: Manipur | C25: 108 | D25: 29.322257 | E25: =VLOOKUP($B25,'[1]8CollegeAct'!$B$5:$AF$40,31,0) -> 1013
A26: 22 | B26: Meghalaya | C26: 77 | D26: 20.248813 | E26: =VLOOKUP($B26,'[1]8CollegeAct'!$B$5:$AF$40,31,0) -> 909
A27: 23 | B27: Mizoram | C27: 40 | D27: 27.601092 | E27: =VLOOKUP($B27,'[1]8CollegeAct'!$B$5:$AF$40,31,0) -> 669
A28: 24 | B28: Nagaland | C28: 69 | D28: 25.26758 | E28: =VLOOKUP($B28,'[1]8CollegeAct'!$B$5:$AF$40,31,0) -> 533
A29: 25 | B29: Odisha | C29: 1300 | D29: 26.710499 | E29: =VLOOKUP($B29,'[1]8CollegeAct'!$B$5:$AF$40,31,0) -> 576
A30: 26 | B30: Puducherry | C30: 82 | D30: 53.322447 | E30: =VLOOKUP($B30,'[1]8CollegeAct'!$B$5:$AF$40,31,0) -> 760
A31: 27 | B31: Punjab | C31: 1044 | D31: 33.301435 | E31: =VLOOKUP($B31,'[1]8CollegeAct'!$B$5:$AF$40,31,0) -> 494
A32: 28 | B32: Rajasthan | C32: 3934 | D32: 41.784387 | E32: =VLOOKUP($B32,'[1]8CollegeAct'!$B$5:$AF$40,31,0) -> 513
A33: 29 | B33: Sikkim | C33: 24 | D33: 27.434246 | E33: =VLOOKUP($B33,'[1]8CollegeAct'!$B$5:$AF$40,31,0) -> 712
A34: 30 | B34: Tamil Nadu | C34: 2829 | D34: 40.218937 | E34: =VLOOKUP($B34,'[1]8CollegeAct'!$B$5:$AF$40,31,0) -> 808
... A40: 36 | B40: West Bengal | C40: 1514 | D40: 14.646416 | E40: =VLOOKUP($B40,'[1]8CollegeAct'!$B$5:$AF$40,31,0) -> 1189
A41: All India | C41: 45473 | D41: 29.827746 | E41: 709
B42: *Average Enroment is calculated on the basis of enrolment including estimation

Sheet New Table 4a Revised
A1: Table 4(a). | C1: Specialisation-wise number of Colleges (Based on Actual Response) | L1: Specialisation-wise number of Colleges (Based on Actual Response) | V1: Specialisation-wise number of Colleges (Based on Actual Response)
A2: S. No. | B2: State/UTs | C2: General | D2: Agriculture | E2: Architecture | F2: Arts | G2: Commerce | H2: Education/Teacher Education | I2: Engineering & Technology | J2: Fine Arts | K2: Fisheries | L2: Home Science | M2: Hotel & Tourism Management | N2: Journalism & Mass Communication | O2: Law | P2: Management | Q2: Medical-Allopathy | R2: Medical-Ayurveda | S2: Medical-Dental | T2: Medical-Homeopathy | U2: Medical-Others | V2: Nursing | W2: Oriental Learning | X2: Others | Y2: Para Medical | Z2: Pharmacy | AA2: Physiotherapy | AB2: Sanskrit | AC2: Science | AD2: Social Work | AE2: Sports/Yoga/Physical Education | AF2: Veterinary | AG2: Grand Total
A3: 1 | B3: 2 | C3: 3 | D3: 4 | E3: 5 | F3: 6 | G3: 7 | H3: 8 | I3: 9 | J3: 10 | K3: 11 | L3: 12 | M3: 13 | N3: 14 | O3: 15 | P3: 16 | Q3: 17 | R3: 18 | S3: 19 | T3: 20 | U3: 21 | V3: 22 | W3: 23 | X3: 24 | Y3: 25 | Z3: 26 | AA3: 27 | AB3: 28 | AC3: 29 | AD3: 30 | AE3: 31 | AF3: 32 | AG3: 33
A4: 1 | B4: A&N Islands | C4: 3 | D4: 0 | F4: 0 | G4: 0 | H4: 1 | I4: 1 | J4: 0 | K4: 0 | L4: 0 | M4: 0 | N4: 0 | O4: 1 | P4: 0 | Q4: 0 | R4: 0 | S4: 0 | T4: 0 | U4: 2 | V4: 0 | W4: 0 | X4: 0 | Y4: 0 | Z4: 0 | AA4: 0 | AB4: 0 | AC4: 1 | AD4: 0 | AE4: 0 | AF4: 0 | AG4: 9
A5: 2 | B5: Andhra Pradesh | C5: 1756 | D5: 36 | E5: 7 | F5: 8 | G5: 3 | H5: 119 | I5: 278 | J5: 1 | K5: 0 | L5: 1 | M5: 7 | N5: 0 | O5: 15 | P5: 39 | Q5: 17 | R5: 2 | S5: 13 | T5: 7 | U5: 18 | V5: 116 | W5: 3 | X5: 8 | Y5: 11 | Z5: 73 | AA5: 24 | AB5: 1 | AC5: 6 | AD5: 0 | AE5: 9 | AF5: 4 | AG5: 2582
A6: 3 | B6: Arunachal Pradesh | C6: 27 | D6: 1 | F6: 2 | G6: 0 | H6: 6 | I6: 0 | J6: 0 | K6: 0 | L6: 0 | M6: 0 | N6: 0 | O6: 2 | P6: 0 | Q6: 1 | R6: 0 | S6: 0 | T6: 1 | U6: 0 | V6: 3 | W6: 0 | X6: 0 | Y6: 0 | Z6: 0 | AA6: 0 | AB6: 0 | AC6: 0 | AD6: 0 | AE6: 0 | AF6: 0 | AG6: 43
A7: 4 | B7: Assam | C7: 368 | D7: 3 | E7: 2 | F7: 40 | G7: 11 | H7: 42 | I7: 11 | J7: 1 | K7: 1 | L7: 0 | M7: 0 | N7: 0 | O7: 18 | P7: 5 | Q7: 3 | R7: 1 | S7: 0 | T7: 2 | U7: 3 | V7: 10 | W7: 0 | X7: 3 | Y7: 5 | Z7: 12 | AA7: 1 | AB7: 1 | AC7: 7 | AD7: 1 | AE7: 0 | AF7: 2 | AG7: 553
A8: 5 | B8: Bihar | C8: 594 | D8: 6 | F8: 18 | G8: 1 | H8: 224 | I8: 61 | J8: 1 | K8: 0 | L8: 0 | M8: 0 | N8: 0 | O8: 17 | P8: 5 | Q8: 11 | R8: 3 | S8: 2 | T8: 6 | U8: 10 | V8: 26 | W8: 0 | X8: 4 | Y8: 8 | Z8: 19 | AA8: 0 | AB8: 55 | AC8: 0 | AD8: 0 | AE8: 0 | AF8: 1 | AG8: 1072
A9: 6 | B9: Chandigarh | C9: 9 | D9: 0 | E9: 1 | F9: 0 | G9: 1 | H9: 4 | I9: 2 | J9: 1 | K9: 0 | L9: 1 | M9: 0 | N9: 0 | O9: 0 | P9: 1 | Q9: 0 | R9: 1 | S9: 0 | T9: 1 | U9: 1 | V9: 0 | W9: 0 | X9: 0 | Y9: 0 | Z9: 0 | AA9: 0 | AB9: 0 | AC9: 0 | AD9: 0 | AE9: 2 | AF9: 1 | AG9: 26
A10: 7 | B10: Chhattisgarh | C10: 542 | D10: 27 | E10: 1 | F10: 8 | G10: 2 | H10: 61 | I10: 70 | J10: 3 | K10: 1 | L10: 0 | M10: 0 | N10: 1 | O10: 10 | P10: 4 | Q10: 6 | R10: 5 | S10: 6 | T10: 3 | U10: 7 | V10: 90 | W10: 0 | X10: 1 | Y10: 0 | Z10: 25 | AA10: 2 | AB10: 4 | AC10: 7 | AD10: 0 | AE10: 3 | AF10: 6 | AG10: 895
A11: 8 | B11: Delhi | C11: 91 | D11: 0 | E11: 2 | F11: 0 | G11: 1 | H11: 12 | I11: 15 | J11: 2 | K11: 0 | L11: 1 | M11: 1 | N11: 1 | O11: 1 | P11: 10 | Q11: 9 | R11: 2 | S11: 2 | T11: 2 | U11: 5 | V11: 6 | W11: 0 | X11: 4 | Y11: 1 | Z11: 1 | AA11: 0 | AB11: 0 | AC11: 0 | AD11: 0 | AE11: 2 | AF11: 0 | AG11: 171
A12: 9 | B12: Goa | C12: 29 | D12: 2 | E12: 1 | F12: 0 | G12: 1 | H12: 4 | I12: 6 | J12: 2 | K12: 0 | L12: 1 | M12: 3 | N12: 0 | O12: 2 | P12: 0 | Q12: 2 | R12: 1 | S12: 1 | T12: 1 | U12: 0 | V12: 2 | W12: 0 | X12: 3 | Y12: 0 | Z12: 1 | AA12: 0 | AB12: 0 | AC12: 0 | AD12: 0 | AE12: 0 | AF12: 0 | AG12: 62
A13: 10 | B13: Gujarat | C13: 914 | D13: 33 | E13: 28 | F13: 115 | G13: 86 | H13: 221 | I13: 239 | J13: 3 | K13: 3 | L13: 3 | M13: 6 | N13: 1 | O13: 59 | P13: 69 | Q13: 21 | R13: 24 | S13: 9 | T13: 30 | U13: 59 | V13: 131 | W13: 1 | X13: 51 | Y13: 23 | Z13: 46 | AA13: 41 | AB13: 21 | AC13: 108 | AD13: 17 | AE13: 5 | AF13: 7 | AG13: 2374
A14: 11 | B14: Haryana | C14: 539 | D14: 4 | E14: 5 | F14: 4 | G14: 0 | H14: 285 | I14: 83 | J14: 0 | K14: 1 | L14: 0 | M14: 2 | N14: 0 | O14: 18 | P14: 22 | Q14: 4 | R14: 5 | S14: 6 | T14: 1 | U14: 7 | V14: 34 | W14: 1 | X14: 6 | Y14: 0 | Z14: 35 | AA14: 5 | AB14: 5 | AC14: 2 | AD14: 0 | AE14: 0 | AF14: 15 | AG14: 1089
A15: 12 | B15: Himachal Pradesh | C15: 196 | D15: 0 | E15: 1 | F15: 2 | G15: 0 | H15: 41 | I15: 15 | J15: 1 | K15: 0 | L15: 0 | M15: 5 | N15: 0 | O15: 6 | P15: 4 | Q15: 1 | R15: 2 | S15: 5 | T15: 1 | U15: 7 | V15: 22 | W15: 1 | X15: 1 | Y15: 0 | Z15: 16 | AA15: 0 | AB15: 17 | AC15: 1 | AD15: 0 | AE15: 1 | AF15: 2 | AG15: 348
A16: 13 | B16: Jammu and Kashmir | C16: 202 | D16: 4 | E16: 2 | F16: 2 | G16: 1 | H16: 68 | I16: 11 | J16: 0 | K16: 1 | L16: 0 | M16: 0 | N16: 0 | O16: 7 | P16: 1 | Q16: 6 | R16: 2 | S16: 3 | T16: 0 | U16: 7 | V16: 10 | W16: 3 | X16: 1 | Y16: 1 | Z16: 1 | AA16: 1 | AB16: 0 | AC16: 0 | AD16: 0 | AE16: 2 | AF16: 1 | AG16: 337
A17: 14 | B17: Jharkhand | C17: 199 | D17: 4 | E17: 2 | F17: 8 | G17: 1 | H17: 79 | I17: 31 | J17: 0 | K17: 0 | L17: 0 | M17: 1 | N17: 0 | O17: 6 | P17: 0 | Q17: 4 | R17: 0 | S17: 3 | T17: 3 | U17: 5 | V17: 13 | W17: 0 | X17: 1 | Y17: 0 | Z17: 1 | AA17: 0 | AB17: 4 | AC17: 0 | AD17: 0 | AE17: 0 | AF17: 0 | AG17: 365
A18: 15 | B18: Karnataka | C18: 2493 | D18: 21 | E18: 31 | F18: 129 | G18: 119 | H18: 157 | I18: 206 | J18: 13 | K18: 1 | L18: 2 | M18: 9 | N18: 2 | O18: 77 | P18: 95 | Q18: 42 | R18: 78 | S18: 37 | T18: 16 | U18: 78 | V18: 388 | W18: 3 | X18: 52 | Y18: 36 | Z18: 76 | AA18: 48 | AB18: 23 | AC18: 20 | AD18: 12 | AE18: 13 | AF18: 6 | AG18: 4283
A19: 16 | B19: Kerala | C19: 643 | D19: 6 | E19: 27 | F19: 50 | G19: 2 | H19: 120 | I19: 141 | J19: 7 | K19: 0 | L19: 1 | M19: 3 | N19: 0 | O19: 14 | P19: 36 | Q19: 16 | R19: 14 | S19: 21 | T19: 6 | U19: 22 | V19: 104 | W19: 7 | X19: 11 | Y19: 27 | Z19: 40 | AA19: 2 | AB19: 3 | AC19: 5 | AD19: 0 | AE19: 1 | AF19: 3 | AG19: 1332
A20: 17 | B20: Ladakh | C20: 5 | D20: 0 | F20: 1 | G20: 0 | H20: 0 | I20: 0 | J20: 0 | K20: 0 | L20: 0 | M20: 0 | N20: 0 | O20: 0 | P20: 0 | Q20: 0 | R20: 0 | S20: 0 | T20: 0 | U20: 0 | V20: 0 | W20: 0 | X20: 0 | Y20: 0 | Z20: 0 | AA20: 0 | AB20: 0 | AC20: 0 | AD20: 0 | AE20: 0 | AF20: 0 | AG20: 6
A21: 18 | B21: Madhya Pradesh | C21: 1426 | D21: 16 | E21: 4 | F21: 41 | G21: 6 | H21: 274 | I21: 175 | J21: 20 | K21: 1 | L21: 1 | M21: 1 | N21: 0 | O21: 52 | P21: 83 | Q21: 7 | R21: 24 | S21: 6 | T21: 11 | U21: 13 | V21: 132 | W21: 3 | X21: 10 | Y21: 36 | Z21: 91 | AA21: 0 | AB21: 8 | AC21: 15 | AD21: 1 | AE21: 2 | AF21: 5 | AG21: 2464
A22: 19 | B22: Maharashtra | C22: 2756 | D22: 107 | E22: 85 | F22: 147 | G22: 69 | H22: 177 | I22: 398 | J22: 22 | K22: 4 | L22: 11 | M22: 22 | N22: 6 | O22: 96 | P22: 97 | Q22: 38 | R22: 59 | S22: 23 | T22: 40 | U22: 34 | V22: 104 | W22: 0 | X22: 53 | Y22: 3 | Z22: 164 | AA22: 47 | AB22: 6 | AC22: 53 | AD22: 39 | AE22: 19 | AF22: 6 | AG22: 4685
A23: 20 | B23: Manipur | C23: 66 | D23: 4 | F23: 0 | G23: 0 | H23: 9 | I23: 7 | J23: 1 | K23: 0 | L23: 0 | M23: 0 | N23: 0 | O23: 1 | P23: 2 | Q23: 0 | R23: 0 | S23: 1 | T23: 0 | U23: 2 | V23: 6 | W23: 0 | X23: 0 | Y23: 0 | Z23: 0 | AA23: 0 | AB23: 0 | AC23: 1 | AD23: 3 | AE23: 0 | AF23: 0 | AG23: 103
A24: 21 | B24: Meghalaya | C24: 48 | D24: 1 | F24: 9 | G24: 1 | H24: 4 | I24: 1 | J24: 0 | K24: 0 | L24: 0 | M24: 0 | N24: 0 | O24: 2 | P24: 0 | Q24: 0 | R24: 0 | S24: 0 | T24: 0 | U24: 0 | V24: 1 | W24: 0 | X24: 1 | Y24: 0 | Z24: 0 | AA24: 0 | AB24: 0 | AC24: 1 | AD24: 0 | AE24: 0 | AF24: 0 | AG24: 69
A25: 22 | B25: Mizoram | C25: 29 | D25: 1 | F25: 0 | G25: 0 | H25: 1 | I25: 1 | J25: 0 | K25: 0 | L25: 0 | M25: 0 | N25: 0 | O25: 1 | P25: 0 | Q25: 1 | R25: 0 | S25: 0 | T25: 0 | U25: 0 | V25: 3 | W25: 0 | X25: 0 | Y25: 1 | Z25: 0 | AA25: 0 | AB25: 0 | AC25: 0 | AD25: 1 | AE25: 0 | AF25: 1 | AG25: 40
A26: 23 | B26: Nagaland | C26: 56 | D26: 0 | F26: 2 | G26: 0 | H26: 5 | I26: 0 | J26: 1 | K26: 0 | L26: 0 | M26: 0 | N26: 0 | O26: 3 | P26: 0 | Q26: 0 | R26: 0 | S26: 0 | T26: 0 | U26: 0 | V26: 1 | W26: 0 | X26: 0 | Y26: 0 | Z26: 0 | AA26: 0 | AB26: 0 | AC26: 0 | AD26: 0 | AE26: 0 | AF26: 0 | AG26: 68
A27: 24 | B27: Odisha | C27: 772 | D27: 0 | E27: 4 | F27: 65 | G27: 2 | H27: 22 | I27: 86 | J27: 10 | K27: 0 | L27: 0 | M27: 22 | N27: 1 | O27: 19 | P27: 56 | Q27: 5 | R27: 4 | S27: 2 | T27: 4 | U27: 12 | V27: 52 | W27: 8 | X27: 17 | Y27: 2 | Z27: 19 | AA27: 4 | AB27: 67 | AC27: 26 | AD27: 2 | AE27: 6 | AF27: 0 | AG27: 1289
A28: 25 | B28: Puducherry | C28: 17 | D28: 1 | E28: 1 | F28: 1 | G28: 0 | H28: 14 | I28: 14 | J28: 1 | K28: 0 | L28: 0 | M28: 0 | N28: 0 | O28: 1 | P28: 0 | Q28: 4 | R28: 0 | S28: 2 | T28: 0 | U28: 0 | V28: 6 | W28: 0 | X28: 1 | Y28: 3 | Z28: 1 | AA28: 0 | AB28: 0 | AC28: 0 | AD28: 0 | AE28: 0 | AF28: 1 | AG28: 68
A29: 26 | B29: Punjab | C29: 483 | D29: 0 | E29: 6 | F29: 22 | G29: 6 | H29: 167 | I29: 83 | J29: 1 | K29: 0 | L29: 0 | M29: 5 | N29: 0 | O29: 19 | P29: 44 | Q29: 9 | R29: 16 | S29: 13 | T29: 3 | U29: 2 | V29: 93 | W29: 0 | X29: 12 | Y29: 4 | Z29: 31 | AA29: 7 | AB29: 0 | AC29: 3 | AD29: 0 | AE29: 7 | AF29: 1 | AG29: 1037
A30: 27 | B30: Rajasthan | C30: 2347 | D30: 22 | E30: 3 | F30: 169 | G30: 5 | H30: 438 | I30: 89 | J30: 2 | K30: 0 | L30: 2 | M30: 4 | N30: 0 | O30: 61 | P30: 15 | Q30: 5 | R30: 14 | S30: 8 | T30: 5 | U30: 16 | V30: 127 | W30: 0 | X30: 13 | Y30: 0 | Z30: 74 | AA30: 7 | AB30: 45 | AC30: 16 | AD30: 0 | AE30: 21 | AF30: 13 | AG30: 3521
A31: 28 | B31: Sikkim | C31: 8 | D31: 0 | F31: 0 | G31: 0 | H31: 3 | I31: 3 | J31: 0 | K31: 0 | L31: 0 | M31: 0 | N31: 0 | O31: 0 | P31: 0 | Q31: 0 | R31: 0 | S31: 0 | T31: 0 | U31: 0 | V31: 1 | W31: 0 | X31: 1 | Y31: 0 | Z31: 2 | AA31: 0 | AB31: 1 | AC31: 1 | AD31: 0 | AE31: 0 | AF31: 0 | AG31: 20
A32: 29 | B32: Tamil Nadu | C32: 1280 | D32: 45 | E32: 47 | F32: 79 | G32: 1 | H32: 263 | I32: 462 | J32: 7 | K32: 7 | L32: 1 | M32: 0 | N32: 0 | O32: 15 | P32: 41 | Q32: 51 | R32: 9 | S32: 18 | T32: 12 | U32: 94 | V32: 163 | W32: 2 | X32: 35 | Y32: 37 | Z32: 56 | AA32: 34 | AB32: 1 | AC32: 13 | AD32: 1 | AE32: 26 | AF32: 7 | AG32: 2807
A33: 30 | B33: Telangana | C33: 1267 | D33: 0 | E33: 10 | F33: 6 | G33: 15 | H33: 97 | I33: 186 | J33: 1 | K33: 0 | L33: 0 | M33: 29 | N33: 1 | O33: 16 | P33: 66 | Q33: 17 | R33: 2 | S33: 11 | T33: 5 | U33: 23 | V33: 56 | W33: 9 | X33: 5 | Y33: 9 | Z33: 84 | AA33: 19 | AB33: 0 | AC33: 4 | AD33: 1 | AE33: 1 | AF33: 0 | AG33: 1940
A34: 31 | B34: The Dadra & Nagar Haveli and Daman & Diu | C34: 6 | D34: 0 | F34: 0 | G34: 0 | H34: 2 | I34: 5 | J34: 0 | K34: 0 | L34: 0 | M34: 0 | N34: 0 | O34: 0 | P34: 0 | Q34: 0 | R34: 0 | S34: 1 | T34: 0 | U34: 1 | V34: 2 | W34: 0 | X34: 1 | Y34: 0 | Z34: 1 | AA34: 0 | AB34: 0 | AC34: 0 | AD34: 0 | AE34: 0 | AF34: 0 | AG34: 19
A35: 32 | B35: Tripura | C35: 28 | D35: 1 | E35: 1 | F35: 0 | G35: 0 | H35: 2 | I35: 7 | J35: 1 | K35: 1 | L35: 0 | M35: 0 | N35: 0 | O35: 1 | P35: 0 | Q35: 2 | R35: 0 | S35: 0 | T35: 0 | U35: 0 | V35: 3 | W35: 0 | X35: 2 | Y35: 1 | Z35: 2 | AA35: 0 | AB35: 0 | AC35: 0 | AD35: 0 | AE35: 1 | AF35: 1 | AG35: 54
A36: 33 | B36: Uttar Pradesh | C36: 5290 | D36: 13 | E36: 18 | F36: 227 | G36: 6 | H36: 381 | I36: 198 | J36: 5 | K36: 0 | L36: 2 | M36: 5 | N36: 1 | O36: 243 | P36: 135 | Q36: 16 | R36: 26 | S36: 17 | T36: 8 | U36: 24 | V36: 26 | W36: 11 | X36: 14 | Y36: 10 | Z36: 143 | AA36: 1 | AB36: 331 | AC36: 27 | AD36: 0 | AE36: 4 | AF36: 0 | AG36: 7182
A37: 34 | B37: Uttarakhand | C37: 218 | D37: 6 | E37: 1 | F37: 6 | G37: 0 | H37: 27 | I37: 31 | J37: 0 | K37: 1 | L37: 1 | M37: 3 | N37: 0 | O37: 10 | P37: 17 | Q37: 3 | R37: 11 | S37: 2 | T37: 0 | U37: 5 | V37: 17 | W37: 1 | X37: 0 | Y37: 7 | Z37: 13 | AA37: 0 | AB37: 16 | AC37: 2 | AD37: 0 | AE37: 3 | AF37: 1 | AG37: 402
A38: 35 | B38: West Bengal | C38: 774 | D38: 0 | E38: 2 | F38: 10 | G38: 2 | H38: 383 | I38: 78 | J38: 7 | K38: 1 | L38: 0 | M38: 5 | N38: 0 | O38: 29 | P38: 34 | Q38: 27 | R38: 4 | S38: 5 | T38: 11 | U38: 17 | V38: 73 | W38: 0 | X38: 13 | Y38: 9 | Z38: 15 | AA38: 4 | AB38: 3 | AC38: 2 | AD38: 0 | AE38: 2 | AF38: 0 | AG38: 1510
A39: All India | C39: 25481 | D39: 364 | E39: 292 | F39: 1171 | G39: 342 | H39: 3713 | I39: 2994 | J39: 114 | K39: 23 | L39: 28 | M39: 133 | N39: 14 | O39: 822 | P39: 881 | Q39: 328 | R39: 309 | S39: 217 | T39: 179 | U39: 474 | V39: 1821 | W39: 53 | X39: 324 | Y39: 234 | Z39: 1042 | AA39: 247 | AB39: 612 | AC39: 321 | AD39: 78 | AE39: 130 | AF39: 84 | AG39: 42825

Sheet 5ManagementCollegeNo
A1: Table | C1: 5. Number of Private and Government Colleges (Based on Actual Response) | H1: 5(a). Enrolment in Private and Government Colleges (Based on Actual Response) | M1: 5(b). Number of Colleges Established in 2021 and their Enrolment (Based on Actual Response)
A2: S.No. | B2: State/UTs | C2: Private (Un-Aided) | D2: Private (Aided) | E2: Private Total | F2: Government | G2: Total | H2: =C2 -> Private (Un-Aided) | I2: =D2 -> Private (Aided) | J2: Private Total | K2: Government | L2: Total | M2: =H2 -> Private (Un-Aided) | O2: =I2 -> Private (Aided) | Q2: Government | S2: Total
M3: Number | N3: Enrolment | O3: Number | P3: Enrolment | Q3: Number | R3: Enrolment | S3: Number | T3: Enrolment
A4: 1 | B4: 2 | C4: 3 | D4: 4 | E4: 5 | F4: 6 | G4: 7 | H4: 8 | I4: 9 | J4: 10 | K4: 11 | L4: 12 | M4: 13 | N4: 14 | O4: 15 | P4: 16 | Q4: 17 | R4: 18 | S4: 19 | T4: 20
A5: 1 | B5: A & N Islands | F5: 9 | G5: 9 | K5: 7272 | L5: 7272 | S5: =Q5+O5+M5 -> 0 | T5: =R5+P5+N5 -> 0
A6: 2 | B6: Andhra Pradesh | C6: 2130 | D6: 136 | E6: 2266 | F6: 316 | G6: 2582 | H6: 1136739 | I6: 98490 | J6: 1235229 | K6: 195090 | L6: 1430319 | M6: =VLOOKUP($B6,[2]Sheet1!$A$3:$I$27,2,0) -> 2 | N6: =VLOOKUP($B6,[2]Sheet1!$A$3:$I$27,3,0) -> 102 | O6: =VLOOKUP($B6,[2]Sheet1!$A$3:$I$27,4,0) -> 0 | P6: =VLOOKUP($B6,[2]Sheet1!$A$3:$I$27,5,0) -> 0 | Q6: =VLOOKUP($B6,[2]Sheet1!$A$3:$I$27,6,0) -> 6 | R6: =VLOOKUP($B6,[2]Sheet1!$A$3:$I$27,7,0) -> 365 | S6: =Q6+O6+M6 -> 8 | T6: =R6+P6+N6 -> 467
A7: 3 | B7: Arunachal Pradesh | C7: 15 | D7: 4 | E7: 19 | F7: 24 | G7: 43 | H7: 6042 | I7: 1340 | J7: 7382 | K7: 21238 | L7: 28620 | S7: =Q7+O7+M7 -> 0 | T7: =R7+P7+N7 -> 0
A8: 4 | B8: Assam | C8: 84 | D8: 25 | E8: 109 | F8: 444 | G8: 553 | H8: 26792 | I8: 5644 | J8: 32436 | K8: 468438 | L8: 500874 | M8: =VLOOKUP($B8,[2]Sheet1!$A$3:$I$27,2,0) -> 3 | N8: =VLOOKUP($B8,[2]Sheet1!$A$3:$I$27,3,0) -> 128 | O8: =VLOOKUP($B8,[2]Sheet1!$A$3:$I$27,4,0) -> 2 | P8: =VLOOKUP($B8,[2]Sheet1!$A$3:$I$27,5,0) -> 60 | Q8: =VLOOKUP($B8,[2]Sheet1!$A$3:$I$27,6,0) -> 0 | R8: =VLOOKUP($B8,[2]Sheet1!$A$3:$I$27,7,0) -> 0 | S8: =Q8+O8+M8 -> 5 | T8: =R8+P8+N8 -> 188
A9: 5 | B9: Bihar | C9: 362 | D9: 170 | E9: 532 | F9: 540 | G9: 1072 | H9: 189493 | I9: 359509 | J9: 549002 | K9: 1689577 | L9: 2238579 | M9: =VLOOKUP($B9,[2]Sheet1!$A$3:$I$27,2,0) -> 13 | N9: =VLOOKUP($B9,[2]Sheet1!$A$3:$I$27,3,0) -> 4242 | O9: =VLOOKUP($B9,[2]Sheet1!$A$3:$I$27,4,0) -> 1 | P9: =VLOOKUP($B9,[2]Sheet1!$A$3:$I$27,5,0) -> 0 | Q9: =VLOOKUP($B9,[2]Sheet1!$A$3:$I$27,6,0) -> 2 | R9: =VLOOKUP($B9,[2]Sheet1!$A$3:$I$27,7,0) -> 156 | S9: =Q9+O9+M9 -> 16 | T9: =R9+P9+N9 -> 4398
A10: 6 | B10: Chandigarh | C10: 4 | D10: 7 | E10: 11 | F10: 15 | G10: 26 | H10: 633 | I10: 29354 | J10: 29987 | K10: 19089 | L10: 49076 | S10: =Q10+O10+M10 -> 0 | T10: =R10+P10+N10 -> 0
A11: 7 | B11: Chhattisgarh | C11: 383 | D11: 90 | E11: 473 | F11: 422 | G11: 895 | H11: 134239 | I11: 40240 | J11: 174479 | K11: 367764 | L11: 542243 | M11: =VLOOKUP($B11,[2]Sheet1!$A$3:$I$27,2,0) -> 6 | N11: =VLOOKUP($B11,[2]Sheet1!$A$3:$I$27,3,0) -> 135 | O11: =VLOOKUP($B11,[2]Sheet1!$A$3:$I$27,4,0) -> 2 | P11: =VLOOKUP($B11,[2]Sheet1!$A$3:$I$27,5,0) -> 267 | Q11: =VLOOKUP($B11,[2]Sheet1!$A$3:$I$27,6,0) -> 26 | R11: =VLOOKUP($B11,[2]Sheet1!$A$3:$I$27,7,0) -> 2655 | S11: =Q11+O11+M11 -> 34 | T11: =R11+P11+N11 -> 3057
A12: 8 | B12: Delhi | C12: 64 | D12: 8 | E12: 72 | F12: 99 | G12: 171 | H12: 64258 | I12: 19057 | J12: 83315 | K12: 216282 | L12: 299597 | M12: =VLOOKUP($B12,[2]Sheet1!$A$3:$I$27,2,0) -> 0 | N12: =VLOOKUP($B12,[2]Sheet1!$A$3:$I$27,3,0) -> 0 | O12: =VLOOKUP($B12,[2]Sheet1!$A$3:$I$27,4,0) -> 0 | P12: =VLOOKUP($B12,[2]Sheet1!$A$3:$I$27,5,0) -> 0 | Q12: =VLOOKUP($B12,[2]Sheet1!$A$3:$I$27,6,0) -> 1 | R12: =VLOOKUP($B12,[2]Sheet1!$A$3:$I$27,7,0) -> 165 | S12: =Q12+O12+M12 -> 1 | T12: =R12+P12+N12 -> 165
A13: 9 | B13: Goa | C13: 15 | D13: 26 | E13: 41 | F13: 21 | G13: 62 | H13: 5262 | I13: 22053 | J13: 27315 | K13: 14820 | L13: 42135 | S13: =Q13+O13+M13 -> 0 | T13: =R13+P13+N13 -> 0
A14: 10 | B14: Gujarat | C14: 1479 | D14: 475 | E14: 1954 | F14: 420 | G14: 2374 | H14: 512494 | I14: 448121 | J14: 960615 | K14: 313906 | L14: 1274521 | M14: =VLOOKUP($B14,[2]Sheet1!$A$3:$I$27,2,0) -> 147 | N14: =VLOOKUP($B14,[2]Sheet1!$A$3:$I$27,3,0) -> 13457 | O14: =VLOOKUP($B14,[2]Sheet1!$A$3:$I$27,4,0) -> 11 | P14: =VLOOKUP($B14,[2]Sheet1!$A$3:$I$27,5,0) -> 1947 | Q14: =VLOOKUP($B14,[2]Sheet1!$A$3:$I$27,6,0) -> 4 | R14: =VLOOKUP($B14,[2]Sheet1!$A$3:$I$27,7,0) -> 513 | S14: =Q14+O14+M14 -> 162 | T14: =R14+P14+N14 -> 15917
A15: 11 | B15: Haryana | C15: 703 | D15: 133 | E15: 836 | F15: 253 | G15: 1089 | H15: 239968 | I15: 164011 | J15: 403979 | K15: 264695 | L15: 668674 | M15: =VLOOKUP($B15,[2]Sheet1!$A$3:$I$27,2,0) -> 6 | N15: =VLOOKUP($B15,[2]Sheet1!$A$3:$I$27,3,0) -> 722 | O15: =VLOOKUP($B15,[2]Sheet1!$A$3:$I$27,4,0) -> 1 | P15: =VLOOKUP($B15,[2]Sheet1!$A$3:$I$27,5,0) -> 100 | Q15: =VLOOKUP($B15,[2]Sheet1!$A$3:$I$27,6,0) -> 3 | R15: =VLOOKUP($B15,[2]Sheet1!$A$3:$I$27,7,0) -> 412 | S15: =Q15+O15+M15 -> 10 | T15: =R15+P15+N15 -> 1234
A16: 12 | B16: Himachal Pradesh | C16: 168 | D16: 16 | E16: 184 | F16: 164 | G16: 348 | H16: 32988 | I16: 11780 | J16: 44768 | K16: 155889 | L16: 200657 | S16: =Q16+O16+M16 -> 0 | T16: =R16+P16+N16 -> 0
A17: 13 | B17: Jammu and Kashmir | C17: 127 | D17: 21 | E17: 148 | F17: 189 | G17: 337 | H17: 23580 | I17: 4038 | J17: 27618 | K17: 185595 | L17: 213213 | M17: =VLOOKUP($B17,[2]Sheet1!$A$3:$I$27,2,0) -> 1 | N17: =VLOOKUP($B17,[2]Sheet1!$A$3:$I$27,3,0) -> 23 | O17: =VLOOKUP($B17,[2]Sheet1!$A$3:$I$27,4,0) -> 0 | P17: =VLOOKUP($B17,[2]Sheet1!$A$3:$I$27,5,0) -> 0 | Q17: =VLOOKUP($B17,[2]Sheet1!$A$3:$I$27,6,0) -> 0 | R17: =VLOOKUP($B17,[2]Sheet1!$A$3:$I$27,7,0) -> 0 | S17: =Q17+O17+M17 -> 1 | T17: =R17+P17+N17 -> 23
A18: 14 | B18: Jharkhand | C18: 160 | D18: 41 | E18: 201 | F18: 164 | G18: 365 | H18: 76012 | I18: 98436 | J18: 174448 | K18: 499915 | L18: 674363 | M18: =VLOOKUP($B18,[2]Sheet1!$A$3:$I$27,2,0) -> 5 | N18: =VLOOKUP($B18,[2]Sheet1!$A$3:$I$27,3,0) -> 1398 | O18: =VLOOKUP($B18,[2]Sheet1!$A$3:$I$27,4,0) -> 1 | P18: =VLOOKUP($B18,[2]Sheet1!$A$3:$I$27,5,0) -> 180 | Q18: =VLOOKUP($B18,[2]Sheet1!$A$3:$I$27,6,0) -> 0 | R18: =VLOOKUP($B18,[2]Sheet1!$A$3:$I$27,7,0) -> 0 | S18: =Q18+O18+M18 -> 6 | T18: =R18+P18+N18 -> 1578
A19: 15 | B19: Karnataka | C19: 3087 | D19: 492 | E19: 3579 | F19: 704 | G19: 4283 | H19: 912471 | I19: 331794 | J19: 1244265 | K19: 524818 | L19: 1769083 | M19: =VLOOKUP($B19,[2]Sheet1!$A$3:$I$27,2,0) -> 79 | N19: =VLOOKUP($B19,[2]Sheet1!$A$3:$I$27,3,0) -> 2796 | O19: =VLOOKUP($B19,[2]Sheet1!$A$3:$I$27,4,0) -> 1 | P19: =VLOOKUP($B19,[2]Sheet1!$A$3:$I$27,5,0) -> 150 | Q19: =VLOOKUP($B19,[2]Sheet1!$A$3:$I$27,6,0) -> 16 | R19: =VLOOKUP($B19,[2]Sheet1!$A$3:$I$27,7,0) -> 914 | S19: =Q19+O19+M19 -> 96 | T19: =R19+P19+N19 -> 3860
A20: 16 | B20: Kerala | C20: 830 | D20: 222 | E20: 1052 | F20: 280 | G20: 1332 | H20: 366522 | I20: 281085 | J20: 647607 | K20: 143053 | L20: 790660 | M20: =VLOOKUP($B20,[2]Sheet1!$A$3:$I$27,2,0) -> 2 | N20: =VLOOKUP($B20,[2]Sheet1!$A$3:$I$27,3,0) -> 18 | O20: =VLOOKUP($B20,[2]Sheet1!$A$3:$I$27,4,0) -> 0 | P20: =VLOOKUP($B20,[2]Sheet1!$A$3:$I$27,5,0) -> 0 | Q20: =VLOOKUP($B20,[2]Sheet1!$A$3:$I$27,6,0) -> 0 | R20: =VLOOKUP($B20,[2]Sheet1!$A$3:$I$27,7,0) -> 0 | S20: =Q20+O20+M20 -> 2 | T20: =R20+P20+N20 -> 18
A21: 17 | B21: Ladakh | F21: 6 | G21: 6 | K21: 3081 | L21: 3081 | S21: =Q21+O21+M21 -> 0 | T21: =R21+P21+N21 -> 0
A22: 18 | B22: Madhya Pradesh | C22: 1398 | D22: 293 | E22: 1691 | F22: 773 | G22: 2464 | H22: 640006 | I22: 168516 | J22: 808522 | K22: 1181770 | L22: 1990292 | M22: =VLOOKUP($B22,[2]Sheet1!$A$3:$I$27,2,0) -> 40 | N22: =VLOOKUP($B22,[2]Sheet1!$A$3:$I$27,3,0) -> 4996 | O22: =VLOOKUP($B22,[2]Sheet1!$A$3:$I$27,4,0) -> 10 | P22: =VLOOKUP($B22,[2]Sheet1!$A$3:$I$27,5,0) -> 1236 | Q22: =VLOOKUP($B22,[2]Sheet1!$A$3:$I$27,6,0) -> 11 | R22: =VLOOKUP($B22,[2]Sheet1!$A$3:$I$27,7,0) -> 951 | S22: =Q22+O22+M22 -> 61 | T22: =R22+P22+N22 -> 7183
A23: 19 | B23: Maharashtra | C23: 2976 | D23: 1167 | E23: 4143 | F23: 542 | G23: 4685 | H23: 1345493 | I23: 1539294 | J23: 2884787 | K23: 322132 | L23: 3206919 | M23: =VLOOKUP($B23,[2]Sheet1!$A$3:$I$27,2,0) -> 138 | N23: =VLOOKUP($B23,[2]Sheet1!$A$3:$I$27,3,0) -> 14028 | O23: =VLOOKUP($B23,[2]Sheet1!$A$3:$I$27,4,0) -> 1 | P23: =VLOOKUP($B23,[2]Sheet1!$A$3:$I$27,5,0) -> 0 | Q23: =VLOOKUP($B23,[2]Sheet1!$A$3:$I$27,6,0) -> 5 | R23: =VLOOKUP($B23,[2]Sheet1!$A$3:$I$27,7,0) -> 747 | S23: =Q23+O23+M23 -> 144 | T23: =R23+P23+N23 -> 14775
A24: 20 | B24: Manipur | C24: 26 | D24: 19 | E24: 45 | F24: 58 | G24: 103 | H24: 6160 | I24: 21242 | J24: 27402 | K24: 76906 | L24: 104308 | S24: =Q24+O24+M24 -> 0 | T24: =R24+P24+N24 -> 0
A25: 21 | B25: Meghalaya | C25: 23 | D25: 17 | E25: 40 | F25: 29 | G25: 69 | H25: 9530 | I25: 19396 | J25: 28926 | K25: 33764 | L25: 62690 | M25: =VLOOKUP($B25,[2]Sheet1!$A$3:$I$27,2,0) -> 3 | N25: =VLOOKUP($B25,[2]Sheet1!$A$3:$I$27,3,0) -> 107 | O25: =VLOOKUP($B25,[2]Sheet1!$A$3:$I$27,4,0) -> 0 | P25: =VLOOKUP($B25,[2]Sheet1!$A$3:$I$27,5,0) -> 0 | Q25: =VLOOKUP($B25,[2]Sheet1!$A$3:$I$27,6,0) -> 0 | R25: =VLOOKUP($B25,[2]Sheet1!$A$3:$I$27,7,0) -> 0 | S25: =Q25+O25+M25 -> 3 | T25: =R25+P25+N25 -> 107
A26: 22 | B26: Mizoram | C26: 8 | D26: 1 | E26: 9 | F26: 31 | G26: 40 | H26: 1599 | I26: 26 | J26: 1625 | K26: 25123 | L26: 26748 | S26: =Q26+O26+M26 -> 0 | T26: =R26+P26+N26 -> 0
A27: 23 | B27: Nagaland | C27: 15 | D27: 32 | E27: 47 | F27: 21 | G27: 68 | H27: 3825 | I27: 14818 | J27: 18643 | K27: 17608 | L27: 36251 | M27: =VLOOKUP($B27,[2]Sheet1!$A$3:$I$27,2,0) -> 1 | N27: =VLOOKUP($B27,[2]Sheet1!$A$3:$I$27,3,0) -> 45 | O27: =VLOOKUP($B27,[2]Sheet1!$A$3:$I$27,4,0) -> 0 | P27: =VLOOKUP($B27,[2]Sheet1!$A$3:$I$27,5,0) -> 0 | Q27: =VLOOKUP($B27,[2]Sheet1!$A$3:$I$27,6,0) -> 0 | R27: =VLOOKUP($B27,[2]Sheet1!$A$3:$I$27,7,0) -> 0 | S27: =Q27+O27+M27 -> 1 | T27: =R27+P27+N27 -> 45
A28: 24 | B28: Odisha | C28: 454 | D28: 443 | E28: 897 | F28: 392 | G28: 1289 | H28: 182663 | I28: 294208 | J28: 476871 | K28: 265860 | L28: 742731 | M28: =VLOOKUP($B28,[2]Sheet1!$A$3:$I$27,2,0) -> 11 | N28: =VLOOKUP($B28,[2]Sheet1!$A$3:$I$27,3,0) -> 557 | O28: =VLOOKUP($B28,[2]Sheet1!$A$3:$I$27,4,0) -> 3 | P28: =VLOOKUP($B28,[2]Sheet1!$A$3:$I$27,5,0) -> 234 | Q28: =VLOOKUP($B28,[2]Sheet1!$A$3:$I$27,6,0) -> 4 | R28: =VLOOKUP($B28,[2]Sheet1!$A$3:$I$27,7,0) -> 351 | S28: =Q28+O28+M28 -> 18 | T28: =R28+P28+N28 -> 1142
A29: 25 | B29: Puducherry | C29: 43 | D29: 1 | E29: 44 | F29: 24 | G29: 68 | H29: 24701 | I29: 100 | J29: 24801 | K29: 26849 | L29: 51650 | S29: =Q29+O29+M29 -> 0 | T29: =R29+P29+N29 -> 0
A30: 26 | B30: Punjab | C30: 653 | D30: 179 | E30: 832 | F30: 205 | G30: 1037 | H30: 213361 | I30: 152321 | J30: 365682 | K30: 147075 | L30: 512757 | M30: =VLOOKUP($B30,[2]Sheet1!$A$3:$I$27,2,0) -> 14 | N30: =VLOOKUP($B30,[2]Sheet1!$A$3:$I$27,3,0) -> 861 | O30: =VLOOKUP($B30,[2]Sheet1!$A$3:$I$27,4,0) -> 2 | P30: =VLOOKUP($B30,[2]Sheet1!$A$3:$I$27,5,0) -> 10 | Q30: =VLOOKUP($B30,[2]Sheet1!$A$3:$I$27,6,0) -> 14 | R30: =VLOOKUP($B30,[2]Sheet1!$A$3:$I$27,7,0) -> 1281 | S30: =Q30+O30+M30 -> 30 | T30: =R30+P30+N30 -> 2152
A31: 27 | B31: Rajasthan | C31: 2448 | D31: 275 | E31: 2723 | F31: 798 | G31: 3521 | H31: 987064 | I31: 103673 | J31: 1090737 | K31: 716025 | L31: 1806762 | M31: =VLOOKUP($B31,[2]Sheet1!$A$3:$I$27,2,0) -> 65 | N31: =VLOOKUP($B31,[2]Sheet1!$A$3:$I$27,3,0) -> 3850 | O31: =VLOOKUP($B31,[2]Sheet1!$A$3:$I$27,4,0) -> 7 | P31: =VLOOKUP($B31,[2]Sheet1!$A$3:$I$27,5,0) -> 594 | Q31: =VLOOKUP($B31,[2]Sheet1!$A$3:$I$27,6,0) -> 65 | R31: =VLOOKUP($B31,[2]Sheet1!$A$3:$I$27,7,0) -> 7646 | S31: =Q31+O31+M31 -> 137 | T31: =R31+P31+N31 -> 12090
A32: 28 | B32: Sikkim | C32: 4 | E32: 4 | F32: 16 | G32: 20 | H32: 1061 | J32: 1061 | K32: 13186 | L32: 14247 | S32: =Q32+O32+M32 -> 0 | T32: =R32+P32+N32 -> 0
A33: 29 | B33: Tamil Nadu | C33: 2128 | D33: 265 | E33: 2393 | F33: 414 | G33: 2807 | H33: 1310938 | I33: 467202 | J33: 1778140 | K33: 489763 | L33: 2267903 | M33: =VLOOKUP($B33,[2]Sheet1!$A$3:$I$27,2,0) -> 48 | N33: =VLOOKUP($B33,[2]Sheet1!$A$3:$I$27,3,0) -> 2752 | O33: =VLOOKUP($B33,[2]Sheet1!$A$3:$I$27,4,0) -> 1 | P33: =VLOOKUP($B33,[2]Sheet1!$A$3:$I$27,5,0) -> 60 | Q33: =VLOOKUP($B33,[2]Sheet1!$A$3:$I$27,6,0) -> 23 | R33: =VLOOKUP($B33,[2]Sheet1!$A$3:$I$27,7,0) -> 2591 | S33: =Q33+O33+M33 -> 72 | T33: =R33+P33+N33 -> 5403
A34: 30 | B34: Telangana | C34: 1548 | D34: 109 | E34: 1657 | F34: 283 | G34: 1940 | H34: 892333 | I34: 85610 | J34: 977943 | K34: 208133 | L34: 1186076 | M34: =VLOOKUP($B34,[2]Sheet1!$A$3:$I$27,2,0) -> 5 | N34: =VLOOKUP($B34,[2]Sheet1!$A$3:$I$27,3,0) -> 887 | O34: =VLOOKUP($B34,[2]Sheet1!$A$3:$I$27,4,0) -> 0 | P34: =VLOOKUP($B34,[2]Sheet1!$A$3:$I$27,5,0) -> 0 | Q34: =VLOOKUP($B34,[2]Sheet1!$A$3:$I$27,6,0) -> 4 | R34: =VLOOKUP($B34,[2]Sheet1!$A$3:$I$27,7,0) -> 461 | S34: =Q34+O34+M34 -> 9 | T34: =R34+P34+N34 -> 1348
A35: 31 | B35: D & N Haveli and Daman & Diu | C35: 8 | D35: 1 | E35: 9 | F35: 10 | G35: 19 | H35: 4569 | J35: 4569 | K35: 7863 | L35: 12432 | S35: =Q35+O35+M35 -> 0 | T35: =R35+P35+N35 -> 0
A36: 32 | B36: Tripura | C36: 7 | D36: 4 | E36: 11 | F36: 43 | G36: 54 | H36: 3328 | I36: 2704 | J36: 6032 | K36: 68869 | L36: 74901 | S36: =Q36+O36+M36 -> 0 | T36: =R36+P36+N36 -> 0
A37: 33 | B37: Uttar Pradesh | C37: 5690 | D37: 670 | E37: 6360 | F37: 822 | G37: 7182 | H37: 3817602 | I37: 989561 | J37: 4807163 | K37: 656299 | L37: 5463462 | M37: =VLOOKUP($B37,[2]Sheet1!$A$3:$I$27,2,0) -> 45 | N37: =VLOOKUP($B37,[2]Sheet1!$A$3:$I$27,3,0) -> 7118 | O37: =VLOOKUP($B37,[2]Sheet1!$A$3:$I$27,4,0) -> 2 | P37: =VLOOKUP($B37,[2]Sheet1!$A$3:$I$27,5,0) -> 436 | Q37: =VLOOKUP($B37,[2]Sheet1!$A$3:$I$27,6,0) -> 4 | R37: =VLOOKUP($B37,[2]Sheet1!$A$3:$I$27,7,0) -> 361 | S37: =Q37+O37+M37 -> 51 | T37: =R37+P37+N37 -> 7915
A38: 34 | B38: Uttarakhand | C38: 199 | D38: 41 | E38: 240 | F38: 162 | G38: 402 | H38: 79425 | I38: 38924 | J38: 118349 | K38: 141323 | L38: 259672 | M38: =VLOOKUP($B38,[2]Sheet1!$A$3:$I$27,2,0) -> 4 | N38: =VLOOKUP($B38,[2]Sheet1!$A$3:$I$27,3,0) -> 257 | O38: =VLOOKUP($B38,[2]Sheet1!$A$3:$I$27,4,0) -> 2 | P38: =VLOOKUP($B38,[2]Sheet1!$A$3:$I$27,5,0) -> 189 | Q38: =VLOOKUP($B38,[2]Sheet1!$A$3:$I$27,6,0) -> 7 | R38: =VLOOKUP($B38,[2]Sheet1!$A$3:$I$27,7,0) -> 1165 | S38: =Q38+O38+M38 -> 13 | T38: =R38+P38+N38 -> 1611
A39: 35 | B39: West Bengal | C39: 717 | D39: 293 | E39: 1010 | F39: 500 | G39: 1510 | H39: 291669 | I39: 429325 | J39: 720994 | K39: 1074264 | L39: 1795258 | M39: =VLOOKUP($B39,[2]Sheet1!$A$3:$I$27,2,0) -> 21 | N39: =VLOOKUP($B39,[2]Sheet1!$A$3:$I$27,3,0) -> 1456 | O39: =VLOOKUP($B39,[2]Sheet1!$A$3:$I$27,4,0) -> 11 | P39: =VLOOKUP($B39,[2]Sheet1!$A$3:$I$27,5,0) -> 270 | Q39: =VLOOKUP($B39,[2]Sheet1!$A$3:$I$27,6,0) -> 9 | R39: =VLOOKUP($B39,[2]Sheet1!$A$3:$I$27,7,0) -> 681 | S39: =Q39+O39+M39 -> 41 | T39: =R39+P39+N39 -> 2407
A40: All India | C40: 27956 | D40: 5676 | E40: 33632 | F40: 9193 | G40: 42825 | H40: 13542820 | I40: 6241872 | J40: 19784692 | K40: 10563334 | L40: 30348026 | M40: =SUM(M5:M39) -> 659 | N40: =SUM(N5:N39) -> 59935 | O40: =SUM(O5:O39) -> 58 | P40: =SUM(P5:P39) -> 5733 | Q40: =SUM(Q5:Q39) -> 204 | R40: =SUM(R5:R39) -> 21415 | S40: =SUM(S5:S39) -> 921 | T40: =SUM(T5:T39) -> 87083

Sheet 6TotalEnr
B1: Table | C1: 6. State-wise Enrolment at various levels (including Estimation) | L1: =C1 -> 6. State-wise Enrolment at various levels (including Estimation) | U1: =C1 -> 6. State-wise Enrolment at various levels (including Estimation)
A2: S.No. | B2: State/UTs | C2: Ph.D. | F2: M.Phil. | I2: Post Graduate | L2: Under Graduate | O2: PG Diploma | R2: Diploma | U2: Certificate | X2: Integrated | AA2: Grand Total
C3: Male | D3: Female | E3: Total | F3: Male | G3: Female | H3: Total | I3: Male | J3: Female | K3: Total | L3: Male | M3: Female | N3: Total | O3: Male | P3: Female | Q3: Total | R3: Male | S3: Female | T3: Total | U3: Male | V3: Female | W3: Total | X3: Male | Y3: Female | Z3: Total | AA3: Male | AB3: Female | AC3: Total
A4: 1 | B4: 2 | C4: 3 | D4: 4 | E4: 5 | F4: 6 | G4: 7 | H4: 8 | I4: 9 | J4: 10 | K4: 11 | L4: 12 | M4: 13 | N4: 14 | O4: 15 | P4: 16 | Q4: 17 | R4: 18 | S4: 19 | T4: 20 | U4: 21 | V4: 22 | W4: 23 | X4: 24 | Y4: 25 | Z4: 26 | AA4: 27 | AB4: 28 | AC4: 29
A5: 1 | B5: A & N Islands | C5: 5 | D5: 9 | E5: 14 | I5: 575 | J5: 942 | K5: 1517 | L5: 3807 | M5: 4444 | N5: 8251 | O5: 26 | P5: 37 | Q5: 63 | R5: 555 | S5: 407 | T5: 962 | U5: 39 | V5: 33 | W5: 72 | X5: 193 | Y5: 355 | Z5: 548 | AA5: 5200 | AB5: 6227 | AC5: 11427
A6: 2 | B6: Andhra Pradesh | C6: 3237 | D6: 2346 | E6: 5583 | F6: 7 | G6: 16 | H6: 23 | I6: 93141 | J6: 91801 | K6: 184942 | L6: 828981 | M6: 740069 | N6: 1569050 | O6: 997 | P6: 574 | Q6: 1571 | R6: 95265 | S6: 61698 | T6: 156963 | U6: 357 | V6: 154 | W6: 511 | X6: 6754 | Y6: 3762 | Z6: 10516 | AA6: 1028739 | AB6: 900420 | AC6: 1929159
A7: 3 | B7: Arunachal Pradesh | C7: 441 | D7: 240 | E7: 681 | I7: 6481 | J7: 6215 | K7: 12696 | L7: 25094 | M7: 21201 | N7: 46295 | O7: 152 | P7: 101 | Q7: 253 | R7: 1335 | S7: 1260 | T7: 2595 | U7: 329 | V7: 163 | W7: 492 | X7: 1163 | Y7: 715 | Z7: 1878 | AA7: 34995 | AB7: 29895 | AC7: 64890
A8: 4 | B8: Assam | C8: 3140 | D8: 2230 | E8: 5370 | F8: 82 | G8: 132 | H8: 214 | I8: 26134 | J8: 36830 | K8: 62964 | L8: 288411 | M8: 290995 | N8: 579406 | O8: 693 | P8: 828 | Q8: 1521 | R8: 12793 | S8: 9470 | T8: 22263 | U8: 102 | V8: 688 | W8: 790 | X8: 2571 | Y8: 2913 | Z8: 5484 | AA8: 333926 | AB8: 344086 | AC8: 678012
A9: 5 | B9: Bihar | C9: 3720 | D9: 1854 | E9: 5574 | I9: 80756 | J9: 74667 | K9: 155423 | L9: 1291227 | M9: 1041776 | N9: 2333003 | O9: 1989 | P9: 808 | Q9: 2797 | R9: 65540 | S9: 53449 | T9: 118989 | U9: 1419 | V9: 1292 | W9: 2711 | X9: 2809 | Y9: 1640 | Z9: 4449 | AA9: 1447460 | AB9: 1175486 | AC9: 2622946
A10: 6 | B10: Chandigarh | C10: 343 | D10: 454 | E10: 797 | F10: 19 | G10: 25 | H10: 44 | I10: 9172 | J10: 13600 | K10: 22772 | L10: 41264 | M10: 36134 | N10: 77398 | O10: 899 | P10: 965 | Q10: 1864 | R10: 2152 | S10: 2828 | T10: 4980 | U10: 319 | V10: 288 | W10: 607 | X10: 1123 | Y10: 1418 | Z10: 2541 | AA10: 55291 | AB10: 55712 | AC10: 111003
A11: 7 | B11: Chhattisgarh | C11: 920 | D11: 917 | E11: 1837 | F11: 4 | G11: 8 | H11: 12 | I11: 35630 | J11: 51834 | K11: 87464 | L11: 227084 | M11: 275545 | N11: 502629 | O11: 8448 | P11: 8480 | Q11: 16928 | R11: 23571 | S11: 18112 | T11: 41683 | U11: 254 | V11: 435 | W11: 689 | X11: 2690 | Y11: 2409 | Z11: 5099 | AA11: 298601 | AB11: 357740 | AC11: 656341
A12: 8 | B12: Delhi | C12: 7533 | D12: 6561 | E12: 14094 | F12: 716 | G12: 761 | H12: 1477 | I12: 73783 | J12: 103616 | K12: 177399 | L12: 473724 | M12: 425006 | N12: 898730 | O12: 8389 | P12: 6686 | Q12: 15075 | R12: 16092 | S12: 13965 | T12: 30057 | U12: 1331 | V12: 1093 | W12: 2424 | X12: 3785 | Y12: 2349 | Z12: 6134 | AA12: 585353 | AB12: 560037 | AC12: 1145390
A13: 9 | B13: Goa | C13: 494 | D13: 407 | E13: 901 | F13: 10 | H13: 10 | I13: 3523 | J13: 4859 | K13: 8382 | L13: 23132 | M13: 22401 | N13: 45533 | O13: 131 | P13: 123 | Q13: 254 | R13: 6515 | S13: 1006 | T13: 7521 | U13: 12 | W13: 12 | X13: 1581 | Y13: 1221 | Z13: 2802 | AA13: 35398 | AB13: 30017 | AC13: 65415
A14: 10 | B14: Gujarat | C14: 4799 | D14: 3734 | E14: 8533 | F14: 35 | G14: 29 | H14: 64 | I14: 97560 | J14: 118747 | K14: 216307 | L14: 775408 | M14: 592468 | N14: 1367876 | O14: 4508 | P14: 4086 | Q14: 8594 | R14: 111752 | S14: 55782 | T14: 167534 | U14: 3245 | V14: 2666 | W14: 5911 | X14: 12359 | Y14: 10484 | Z14: 22843 | AA14: 1009666 | AB14: 787996 | AC14: 1797662
A15: 11 | B15: Haryana | C15: 1784 | D15: 2385 | E15: 4169 | F15: 16 | G15: 32 | H15: 48 | I15: 57199 | J15: 98973 | K15: 156172 | L15: 405310 | M15: 417253 | N15: 822563 | O15: 1801 | P15: 1734 | Q15: 3535 | R15: 63957 | S15: 31839 | T15: 95796 | U15: 298 | V15: 522 | W15: 820 | X15: 11781 | Y15: 9648 | Z15: 21429 | AA15: 542146 | AB15: 562386 | AC15: 1104532
A16: 12 | B16: Himachal Pradesh | C16: 1028 | D16: 1055 | E16: 2083 | F16: 44 | G16: 38 | H16: 82 | I16: 15071 | J16: 18862 | K16: 33933 | L16: 119249 | M16: 141142 | N16: 260391 | O16: 970 | P16: 917 | Q16: 1887 | R16: 8944 | S16: 9189 | T16: 18133 | U16: 333 | V16: 204 | W16: 537 | X16: 1504 | Y16: 1101 | Z16: 2605 | AA16: 147143 | AB16: 172508 | AC16: 319651
A17: 13 | B17: Jammu and Kashmir | C17: 1879 | D17: 1923 | E17: 3802 | F17: 41 | G17: 82 | H17: 123 | I17: 30709 | J17: 41398 | K17: 72107 | L17: 145870 | M17: 147226 | N17: 293096 | O17: 777 | P17: 483 | Q17: 1260 | R17: 9080 | S17: 10909 | T17: 19989 | U17: 410 | V17: 489 | W17: 899 | X17: 4188 | Y17: 4959 | Z17: 9147 | AA17: 192954 | AB17: 207469 | AC17: 400423
A18: 14 | B18: Jharkhand | C18: 2039 | D18: 1113 | E18: 3152 | F18: 14 | G18: 66 | H18: 80 | I18: 48894 | J18: 63574 | K18: 112468 | L18: 362777 | M18: 347379 | N18: 710156 | O18: 2051 | P18: 1087 | Q18: 3138 | R18: 31177 | S18: 14953 | T18: 46130 | U18: 906 | V18: 440 | W18: 1346 | X18: 2248 | Y18: 1247 | Z18: 3495 | AA18: 450106 | AB18: 429859 | AC18: 879965
A19: 15 | B19: Karnataka | C19: 6045 | D19: 5148 | E19: 11193 | F19: 44 | G19: 183 | H19: 227 | I19: 118528 | J19: 142088 | K19: 260616 | L19: 982974 | M19: 923326 | N19: 1906300 | O19: 4862 | P19: 3664 | Q19: 8526 | R19: 134943 | S19: 94970 | T19: 229913 | U19: 1847 | V19: 1196 | W19: 3043 | X19: 8761 | Y19: 7961 | Z19: 16722 | AA19: 1258004 | AB19: 1178536 | AC19: 2436540
A20: 16 | B20: Kerala | C20: 3387 | D20: 5747 | E20: 9134 | F20: 75 | G20: 281 | H20: 356 | I20: 50946 | J20: 121630 | K20: 172576 | L20: 439560 | M20: 576826 | N20: 1016386 | O20: 1284 | P20: 1836 | Q20: 3120 | R20: 53625 | S20: 35512 | T20: 89137 | U20: 580 | V20: 1032 | W20: 1612 | X20: 5115 | Y20: 7009 | Z20: 12124 | AA20: 554572 | AB20: 749873 | AC20: 1304445
A21: 17 | B21: Ladakh | C21: 15 | D21: 3 | E21: 18 | I21: 155 | J21: 318 | K21: 473 | L21: 1187 | M21: 2103 | N21: 3290 | R21: 195 | S21: 314 | T21: 509 | U21: 19 | V21: 131 | W21: 150 | AA21: 1571 | AB21: 2869 | AC21: 4440
A22: 18 | B22: Lakshadweep | L22: 14 | M22: 74 | N22: 88 | AA22: 14 | AB22: 74 | AC22: 88
A23: 19 | B23: Madhya Pradesh | C23: 4283 | D23: 3571 | E23: 7854 | G23: 16 | H23: 16 | I23: 201345 | J23: 239046 | K23: 440391 | L23: 1143205 | M23: 953119 | N23: 2096324 | O23: 21509 | P23: 20506 | Q23: 42015 | R23: 114323 | S23: 61488 | T23: 175811 | U23: 1563 | V23: 858 | W23: 2421 | X23: 19680 | Y23: 15653 | Z23: 35333 | AA23: 1505908 | AB23: 1294257 | AC23: 2800165
A24: 20 | B24: Maharashtra | C24: 10115 | D24: 7717 | E24: 17832 | F24: 121 | G24: 69 | H24: 190 | I24: 283304 | J24: 303894 | K24: 587198 | L24: 1968964 | M24: 1529764 | N24: 3498728 | O24: 25594 | P24: 21182 | Q24: 46776 | R24: 236517 | S24: 157882 | T24: 394399 | U24: 7580 | V24: 4905 | W24: 12485 | X24: 10636 | Y24: 9599 | Z24: 20235 | AA24: 2542831 | AB24: 2035012 | AC24: 4577843
A25: 21 | B25: Manipur | C25: 725 | D25: 723 | E25: 1448 | G25: 6 | H25: 6 | I25: 4940 | J25: 5528 | K25: 10468 | L25: 58171 | M25: 54386 | N25: 112557 | O25: 555 | P25: 419 | Q25: 974 | R25: 1682 | S25: 2967 | T25: 4649 | U25: 161 | V25: 125 | W25: 286 | AA25: 66234 | AB25: 64154 | AC25: 130388
A26: 22 | B26: Meghalaya | C26: 458 | D26: 331 | E26: 789 | F26: 1 | G26: 2 | H26: 3 | I26: 5673 | J26: 8432 | K26: 14105 | L26: 35954 | M26: 41489 | N26: 77443 | O26: 280 | P26: 363 | Q26: 643 | R26: 988 | S26: 2013 | T26: 3001 | U26: 31 | V26: 55 | W26: 86 | X26: 203 | Y26: 180 | Z26: 383 | AA26: 43588 | AB26: 52865 | AC26: 96453
A27: 23 | B27: Mizoram | C27: 634 | D27: 565 | E27: 1199 | I27: 2398 | J27: 3210 | K27: 5608 | L27: 16905 | M27: 16249 | N27: 33154 | O27: 39 | P27: 16 | Q27: 55 | R27: 3200 | S27: 3530 | T27: 6730 | X27: 15 | Y27: 10 | Z27: 25 | AA27: 23191 | AB27: 23580 | AC27: 46771
A28: 24 | B28: Nagaland | C28: 290 | D28: 330 | E28: 620 | F28: 12 | G28: 6 | H28: 18 | I28: 3276 | J28: 5178 | K28: 8454 | L28: 18770 | M28: 20444 | N28: 39214 | O28: 40 | P28: 89 | Q28: 129 | R28: 859 | S28: 1343 | T28: 2202 | U28: 310 | V28: 276 | W28: 586 | AA28: 23557 | AB28: 27666 | AC28: 51223
